Workbook

Sheet ORD DIST.
A1: Q1
A2: n | B2: =ORD!B2 -> 68813
A3: p | B3: =ORD!C9 -> 0.0061879296
A5: Mean | B5: =B2*B3 -> 425.81
A6: Std Dev | B6: =SQRT(B2*B3*(1-B3)) -> 20.571221
A7: Lower 95% | B7: =B5-1.96*B6 -> 385.49041
A8: Upper 95% | B8: =B5+1.96*B6 -> 466.12959
A11: Percentile | B11: Weather delays | C11: ROUNDED | D11: z score value | E11: Binomial PMF (X) | F11: Percentage (%)
A12: =1-0.9901 -> 0.0099 | B12: =_xlfn.NORM.INV(A12,$B$5,$B$6) -> 377.87666 | C12: =ROUND(B12,0) -> 378 | D12: -2.33 | E12: =_xlfn.BINOM.DIST(C12,$B$2,$B$3,FALSE) -> 0.0012418881 | F12: =E12 -> 0.0012418881
A13: =1-0.9495 -> 0.0505 | B13: =_xlfn.NORM.INV(A13,$B$5,$B$6) -> 392.07269 | C13: =ROUND(B13,0) -> 392 | D13: -1.64 | E13: =_xlfn.BINOM.DIST(C13,$B$2,$B$3,FALSE) -> 0.0050439083 | F13: =E13 -> 0.0050439083
A14: =1-0.8997 -> 0.1003 | B14: =_xlfn.NORM.INV(A14,$B$5,$B$6) -> 399.48205 | C14: =ROUND(B14,0) -> 399 | D14: -1.28 | E14: =_xlfn.BINOM.DIST(C14,$B$2,$B$3,FALSE) -> 0.008410464 | F14: =E14 -> 0.008410464
A15: 0.5 | B15: =_xlfn.NORM.INV(A15,$B$5,$B$6) -> 425.81 | C15: =ROUND(B15,0) -> 426 | D15: 0 | E15: =_xlfn.BINOM.DIST(C15,$B$2,$B$3,FALSE) -> 0.019384306 | F15: =E15 -> 0.019384306
A16: 0.8997 | B16: =_xlfn.NORM.INV(A16,$B$5,$B$6) -> 452.13795 | C16: =ROUND(B16,0) -> 452 | D16: 1.28 | E16: =_xlfn.BINOM.DIST(C16,$B$2,$B$3,FALSE) -> 0.008505124 | F16: =E16 -> 0.008505124
A17: 0.9495 | B17: =_xlfn.NORM.INV(A17,$B$5,$B$6) -> 459.54731 | C17: =ROUND(B17,0) -> 460 | D17: 1.64 | E17: =_xlfn.BINOM.DIST(C17,$B$2,$B$3,FALSE) -> 0.0048575391 | F17: =E17 -> 0.0048575391
A18: 0.9901 | B18: =_xlfn.NORM.INV(A18,$B$5,$B$6) -> 473.74334 | C18: =ROUND(B18,0) -> 474 | D18: 2.33 | E18: =_xlfn.BINOM.DIST(C18,$B$2,$B$3,FALSE) -> 0.0013034759 | F18: =E18 -> 0.0013034759
A24: Q2
A25: n | B25: =ORD!B3 -> 78876
A26: p | B26: =ORD!C10 -> 0.0056951417
A28: Mean | B28: =B25*B26 -> 449.21
A29: Std Dev | B29: =SQRT(B25*B26*(1-B26)) -> 21.134136
A30: Lower 95% | B30: =B28-1.96*B29 -> 407.78709
A31: Upper 95% | B31: =B28+1.96*B29 -> 490.63291
A34: Percentile | B34: Weather delays | C34: ROUNDED | D34: z score value | E34: Binomial PMF (X) | F34: Percentage (%)
A35: =1-0.9901 -> 0.0099 | B35: =_xlfn.NORM.INV(A35,$B$28,$B$29) -> 399.965 | C35: =ROUND(B35,0) -> 400 | D35: -2.33 | E35: =_xlfn.BINOM.DIST(C35,$B$25,$B$26,FALSE) -> 0.0011976456 | F35: =E35 -> 0.0011976456
A36: =1-0.9495 -> 0.0505 | B36: =_xlfn.NORM.INV(A36,$B$28,$B$29) -> 414.54949 | C36: =ROUND(B36,0) -> 415 | D36: -1.64 | E36: =_xlfn.BINOM.DIST(C36,$B$25,$B$26,FALSE) -> 0.0051172608 | F36: =E36 -> 0.0051172608
A37: =1-0.8997 -> 0.1003 | B37: =_xlfn.NORM.INV(A37,$B$28,$B$29) -> 422.1616 | C37: =ROUND(B37,0) -> 422 | D37: -1.28 | E37: =_xlfn.BINOM.DIST(C37,$B$25,$B$26,FALSE) -> 0.0083546736 | F37: =E37 -> 0.0083546736
A38: 0.5 | B38: =_xlfn.NORM.INV(A38,$B$28,$B$29) -> 449.21 | C38: =ROUND(B38,0) -> 449 | D38: 0 | E38: =_xlfn.BINOM.DIST(C38,$B$25,$B$26,FALSE) -> 0.018876631 | F38: =E38 -> 0.018876631
A39: 0.8997 | B39: =_xlfn.NORM.INV(A39,$B$28,$B$29) -> 476.2584 | C39: =ROUND(B39,0) -> 476 | D39: 1.28 | E39: =_xlfn.BINOM.DIST(C39,$B$25,$B$26,FALSE) -> 0.0083390983 | F39: =E39 -> 0.0083390983
A40: 0.9495 | B40: =_xlfn.NORM.INV(A40,$B$28,$B$29) -> 483.87051 | C40: =ROUND(B40,0) -> 484 | D40: 1.64 | E40: =_xlfn.BINOM.DIST(C40,$B$25,$B$26,FALSE) -> 0.0048513729 | F40: =E40 -> 0.0048513729
A41: 0.9901 | B41: =_xlfn.NORM.INV(A41,$B$28,$B$29) -> 498.455 | C41: =ROUND(B41,0) -> 498 | D41: 2.33 | E41: =_xlfn.BINOM.DIST(C41,$B$25,$B$26,FALSE) -> 0.0013671928 | F41: =E41 -> 0.0013671928
A47: Q3
A48: n | B48: =ORD!B4 -> 83901
A49: p | B49: =ORD!C11 -> 0.0072523569
A51: Mean | B51: =B48*B49 -> 608.48
A52: Std Dev | B52: =SQRT(B48*B49*(1-B49)) -> 24.577776
A53: Lower 95% | B53: =B51-1.96*B52 -> 560.30756
A54: Upper 95% | B54: =B51+1.96*B52 -> 656.65244
A57: Percentile | B57: Weather delays | C57: ROUNDED | D57: z score value | E57: Binomial PMF (X) | F57: Percentage (%)
A58: =1-0.9901 -> 0.0099 | B58: =_xlfn.NORM.INV(A58,$B$51,$B$52) -> 551.21092 | C58: =ROUND(B58,0) -> 551 | D58: -2.33 | E58: =_xlfn.BINOM.DIST(C58,$B$48,$B$49,FALSE) -> 0.0010116394 | F58: =E58 -> 0.0010116394
A59: =1-0.9495 -> 0.0505 | B59: =_xlfn.NORM.INV(A59,$B$51,$B$52) -> 568.17184 | C59: =ROUND(B59,0) -> 568 | D59: -1.64 | E59: =_xlfn.BINOM.DIST(C59,$B$48,$B$49,FALSE) -> 0.004194533 | F59: =E59 -> 0.004194533
...

Sheet ORD
A1: ORD | B1: Arrival Count | C1: General Delay Count | D1: Weather Delay Count | E1: Non-Weather Delay Count
A2: Q1 (Dec 2014 to Feb 2015) | B2: 68813 | C2: 17920 | D2: 425.81 | E2: =C2-D2 -> 17494.19
A3: Q2 (Mar 2015 to May 2015) | B3: 78876 | C3: 14527 | D3: 449.21 | E3: =C3-D3 -> 14077.79
A4: Q3 (Jun 2015 to Aug 2015) | B4: 83901 | C4: 19129 | D4: 608.48 | E4: =C4-D4 -> 18520.52
A5: Q4 (Sep 2015 to Nov 2015 | B5: 79840 | C5: 11077 | D5: 263.04 | E5: =C5-D5 -> 10813.96
A8: Probability that a flight is delayed due to weather reasons
A9: Weather count delays / No. of arrival flights | B9: Q1 (Dec 2014 to Feb 2015) | C9: =D2/B2 -> 0.0061879296
B10: Q2 (Mar 2015 to May 2015) | C10: =D3/B3 -> 0.0056951417
B11: Q3 (Jun 2015 to Aug 2015) | C11: =D4/B4 -> 0.0072523569
B12: Q4 (Sep 2015 to Nov 2015 | C12: =D5/B5 -> 0.0032945892
A16: Probability that a flight is delayed due to non-weather reasons
A17: Non-weather delays / Arrival flight total | B17: Q1 (Dec 2014 to Feb 2015) | C17: =E2/B2 -> 0.25422798
B18: Q2 (Mar 2015 to May 2015) | C18: =E3/B3 -> 0.17848002
B19: Q3 (Jun 2015 to Aug 2015) | C19: =E4/B4 -> 0.22074254
B20: Q4 (Sep 2015 to Nov 2015 | C20: =E5/B5 -> 0.13544539
A23: Probability that a flight experiences any delay
A24: Non weather delays + Weather delays | B24: Q1 (Dec 2014 to Feb 2015) | C24: =C9+C17 -> 0.26041591
A25: Arrival delays / arrival flights | B25: Q2 (Mar 2015 to May 2015) | C25: =C10+C18 -> 0.18417516
B26: Q3 (Jun 2015 to Aug 2015) | C26: =C11+C19 -> 0.2279949
B27: Q4 (Sep 2015 to Nov 2015 | C27: =C12+C20 -> 0.13873998

Sheet MCO DIST.
A1: Q1
A2: n | B2: =MCO!B2 -> 29065
A3: p | B3: =MCO!C9 -> 0.0062442801
A5: Mean | B5: =B2*B3 -> 181.49
A6: Std Dev | B6: =SQRT(B2*B3*(1-B3)) -> 13.429696
A7: Lower 95% | B7: =B5-1.96*B6 -> 155.1678
A8: Upper 95% | B8: =B5+1.96*B6 -> 207.8122
A11: Percentile | B11: Weather delays | C11: ROUNDED | D11: z score value | E11: Binomial PMF (X) | F11: Percentage (%)
A12: =1-0.9901 -> 0.0099 | B12: =_xlfn.NORM.INV(A12,$B$5,$B$6) -> 150.19725 | C12: =ROUND(B12,0) -> 150 | D12: -2.33 | E12: =_xlfn.BINOM.DIST(C12,$B$2,$B$3,FALSE) -> 0.0017562138 | F12: =E12 -> 0.0017562138
A13: =1-0.9495 -> 0.0505 | B13: =_xlfn.NORM.INV(A13,$B$5,$B$6) -> 159.46497 | C13: =ROUND(B13,0) -> 159 | D13: -1.64 | E13: =_xlfn.BINOM.DIST(C13,$B$2,$B$3,FALSE) -> 0.0073371457 | F13: =E13 -> 0.0073371457
A14: =1-0.8997 -> 0.1003 | B14: =_xlfn.NORM.INV(A14,$B$5,$B$6) -> 164.30208 | C14: =ROUND(B14,0) -> 164 | D14: -1.28 | E14: =_xlfn.BINOM.DIST(C14,$B$2,$B$3,FALSE) -> 0.012996853 | F14: =E14 -> 0.012996853
A15: 0.5 | B15: =_xlfn.NORM.INV(A15,$B$5,$B$6) -> 181.49 | C15: =ROUND(B15,0) -> 181 | D15: 0 | E15: =_xlfn.BINOM.DIST(C15,$B$2,$B$3,FALSE) -> 0.029712417 | F15: =E15 -> 0.029712417
A16: 0.8997 | B16: =_xlfn.NORM.INV(A16,$B$5,$B$6) -> 198.67792 | C16: =ROUND(B16,0) -> 199 | D16: 1.28 | E16: =_xlfn.BINOM.DIST(C16,$B$2,$B$3,FALSE) -> 0.012442556 | F16: =E16 -> 0.012442556
A17: 0.9495 | B17: =_xlfn.NORM.INV(A17,$B$5,$B$6) -> 203.51503 | C17: =ROUND(B17,0) -> 204 | D17: 1.64 | E17: =_xlfn.BINOM.DIST(C17,$B$2,$B$3,FALSE) -> 0.0072610968 | F17: =E17 -> 0.0072610968
A18: 0.9901 | B18: =_xlfn.NORM.INV(A18,$B$5,$B$6) -> 212.78275 | C18: =ROUND(B18,0) -> 213 | D18: 2.33 | E18: =_xlfn.BINOM.DIST(C18,$B$2,$B$3,FALSE) -> 0.0020233413 | F18: =E18 -> 0.0020233413
A24: Q2
A25: n | B25: =MCO!B3 -> 32161
A26: p | B26: =MCO!C10 -> 0.0043126768
A28: Mean | B28: =B25*B26 -> 138.7
A29: Std Dev | B29: =SQRT(B25*B26*(1-B26)) -> 11.751674
A30: Lower 95% | B30: =B28-1.96*B29 -> 115.66672
A31: Upper 95% | B31: =B28+1.96*B29 -> 161.73328
A34: Percentile | B34: Weather delays | C34: ROUNDED | D34: z score value | E34: Binomial PMF (X) | F34: Percentage (%)
A35: =1-0.9901 -> 0.0099 | B35: =_xlfn.NORM.INV(A35,$B$28,$B$29) -> 111.31723 | C35: =ROUND(B35,0) -> 111 | D35: -2.33 | E35: =_xlfn.BINOM.DIST(C35,$B$25,$B$26,FALSE) -> 0.0019193363 | F35: =E35 -> 0.0019193363
A36: =1-0.9495 -> 0.0505 | B36: =_xlfn.NORM.INV(A36,$B$28,$B$29) -> 119.42696 | C36: =ROUND(B36,0) -> 119 | D36: -1.64 | E36: =_xlfn.BINOM.DIST(C36,$B$25,$B$26,FALSE) -> 0.0083640272 | F36: =E36 -> 0.0083640272
A37: =1-0.8997 -> 0.1003 | B37: =_xlfn.NORM.INV(A37,$B$28,$B$29) -> 123.65969 | C37: =ROUND(B37,0) -> 124 | D37: -1.28 | E37: =_xlfn.BINOM.DIST(C37,$B$25,$B$26,FALSE) -> 0.01593472 | F37: =E37 -> 0.01593472
A38: 0.5 | B38: =_xlfn.NORM.INV(A38,$B$28,$B$29) -> 138.7 | C38: =ROUND(B38,0) -> 139 | D38: 0 | E38: =_xlfn.BINOM.DIST(C38,$B$25,$B$26,FALSE) -> 0.033879846 | F38: =E38 -> 0.033879846
A39: 0.8997 | B39: =_xlfn.NORM.INV(A39,$B$28,$B$29) -> 153.74031 | C39: =ROUND(B39,0) -> 154 | D39: 1.28 | E39: =_xlfn.BINOM.DIST(C39,$B$25,$B$26,FALSE) -> 0.014212121 | F39: =E39 -> 0.014212121
A40: 0.9495 | B40: =_xlfn.NORM.INV(A40,$B$28,$B$29) -> 157.97304 | C40: =ROUND(B40,0) -> 158 | D40: 1.64 | E40: =_xlfn.BINOM.DIST(C40,$B$25,$B$26,FALSE) -> 0.0087506454 | F40: =E40 -> 0.0087506454
A41: 0.9901 | B41: =_xlfn.NORM.INV(A41,$B$28,$B$29) -> 166.08277 | C41: =ROUND(B41,0) -> 166 | D41: 2.33 | E41: =_xlfn.BINOM.DIST(C41,$B$25,$B$26,FALSE) -> 0.0024529893 | F41: =E41 -> 0.0024529893
A47: Q3
A48: n | B48: =MCO!B4 -> 30442
A49: p | B49: =MCO!C11 -> 0.0091331056
A51: Mean | B51: =B48*B49 -> 278.03
A52: Std Dev | B52: =SQRT(B48*B49*(1-B49)) -> 16.597913
A53: Lower 95% | B53: =B51-1.96*B52 -> 245.49809
A54: Upper 95% | B54: =B51+1.96*B52 -> 310.56191
A57: Percentile | B57: Weather delays | C57: ROUNDED | D57: z score value | E57: Binomial PMF (X) | F57: Percentage (%)
A58: =1-0.9901 -> 0.0099 | B58: =_xlfn.NORM.INV(A58,$B$51,$B$52) -> 239.35493 | C58: =ROUND(B58,0) -> 239 | D58: -2.33 | E58: =_xlfn.BINOM.DIST(C58,$B$48,$B$49,FALSE) -> 0.0014210334 | F58: =E58 -> 0.0014210334
A59: =1-0.9495 -> 0.0505 | B59: =_xlfn.NORM.INV(A59,$B$51,$B$52) -> 250.80901 | C59: =ROUND(B59,0) -> 251 | D59: -1.64 | E59: =_xlfn.BINOM.DIST(C59,$B$48,$B$49,FALSE) -> 0.0064178772 | F59: =E59 -> 0.0064178772
...

Sheet MCO
A1: MCO | B1: Arrival Count | C1: General Delay Count | D1: Weather Delay Count | E1: Non-Weather Delay Count
A2: Q1 (Dec 2014 to Feb 2015) | B2: 29065 | C2: 6253 | D2: 181.49 | E2: =C2-D2 -> 6071.51
A3: Q2 (Mar 2015 to May 2015) | B3: 32161 | C3: 5850 | D3: 138.7 | E3: =C3-D3 -> 5711.3
A4: Q3 (Jun 2015 to Aug 2015) | B4: 30442 | C4: 7201 | D4: 278.03 | E4: =C4-D4 -> 6922.97
A5: Q4 (Sep 2015 to Nov 2015 | B5: 27316 | C5: 3848 | D5: 80.2 | E5: =C5-D5 -> 3767.8
A8: Probability that a flight is delayed due to weather reasons
A9: Weather count delays / No. of arrival flights | B9: Q1 (Dec 2014 to Feb 2015) | C9: =D2/B2 -> 0.0062442801
B10: Q2 (Mar 2015 to May 2015) | C10: =D3/B3 -> 0.0043126768
B11: Q3 (Jun 2015 to Aug 2015) | C11: =D4/B4 -> 0.0091331056
B12: Q4 (Sep 2015 to Nov 2015 | C12: =D5/B5 -> 0.0029360082
A16: Probability that a flight is delayed due to non-weather reasons
A17: Non-weather delays / Arrival flight total | B17: Q1 (Dec 2014 to Feb 2015) | C17: =E2/B2 -> 0.2088942
B18: Q2 (Mar 2015 to May 2015) | C18: =E3/B3 -> 0.17758465
B19: Q3 (Jun 2015 to Aug 2015) | C19: =E4/B4 -> 0.22741508
B20: Q4 (Sep 2015 to Nov 2015 | C20: =E5/B5 -> 0.13793381
A23: Probability that a flight experiences any delay
A24: Non weather delays + Weather delays | B24: Q1 (Dec 2014 to Feb 2015) | C24: =C9+C17 -> 0.21513848
A25: Arrival delays / arrival flights | B25: Q2 (Mar 2015 to May 2015) | C25: =C10+C18 -> 0.18189733
B26: Q3 (Jun 2015 to Aug 2015) | C26: =C11+C19 -> 0.23654819
B27: Q4 (Sep 2015 to Nov 2015 | C27: =C12+C20 -> 0.14086982
